Workbook
Name IQ_CH: 110000
Name IQ_CQ: 5000
Name IQ_CY: 10000
Name IQ_DAILY: 500000
Name IQ_FH: 100000
Name IQ_FQ: 500
Name IQ_FY: 1000
Name IQ_LTM: 2000
Name IQ_MONTH: 15000
Name IQ_NTM: 6000
Name IQ_WEEK: 50000
Name IQ_YTD: 3000

Sheet Dates
A1: Forecast Month - | D1: October 2026
A2: Modeling and analysis completion - | D2: 46296 | G2: ="EIA completed modeling and analysis for this report on "&TEXT(Dates!$D$2,"dddd, mmmm d, yyyy")&"." -> EIA completed modeling and analysis for this report on Thursday, October 1, 2026.
A3: Table Beginning Year--- | D3: =YEAR(D1)-4 -> 2022
A5: Table Beginning Month--- | D5: =+D3*100+1 -> 202201
A7: Last Historical Month--- | D7: =IF(MONTH(D1)>1,100*YEAR(D1)+MONTH(D1)-1,100*(YEAR(D1)-1)+12) -> 202609
A9: Dataprep timestamp--- | D9: 46296.723
A10: Domestic Tables:
B11: AAAA_DATEX or AAAA_YEAR | C11: =+D5 -> 202201 | D11: =C11+1 -> 202202 | E11: =D11+1 -> 202203 | F11: =E11+1 -> 202204 | G11: =F11+1 -> 202205 | H11: =G11+1 -> 202206 | I11: =H11+1 -> 202207 | J11: =I11+1 -> 202208 | K11: =J11+1 -> 202209 | ... N11: =M11+1 -> 202212 | O11: =+C11+100 -> 202301 | P11: =O11+1 -> 202302 | Q11: =P11+1 -> 202303 | R11: =Q11+1 -> 202304 | S11: =R11+1 -> 202305 | T11: =S11+1 -> 202306 | U11: =T11+1 -> 202307 | V11: =U11+1 -> 202308 | W11: =V11+1 -> 202309 | ... Z11: =Y11+1 -> 202312 | AA11: =+O11+100 -> 202401 | AB11: =AA11+1 -> 202402 | AC11: =AB11+1 -> 202403 | AD11: =AC11+1 -> 202404 | AE11: =AD11+1 -> 202405 | AF11: =AE11+1 -> 202406 | AG11: =AF11+1 -> 202407 | AH11: =AG11+1 -> 202408 | AI11: =AH11+1 -> 202409 | ... AL11: =AK11+1 -> 202412 | AM11: =+AA11+100 -> 202501 | AN11: =AM11+1 -> 202502 | AO11: =AN11+1 -> 202503 | AP11: =AO11+1 -> 202504 | AQ11: =AP11+1 -> 202505 | AR11: =AQ11+1 -> 202506 | AS11: =AR11+1 -> 202507 | AT11: =AS11+1 -> 202508 | AU11: =AT11+1 -> 202509 | ... AX11: =AW11+1 -> 202512 | AY11: =+AM11+100 -> 202601 | AZ11: =AY11+1 -> 202602 | BA11: =AZ11+1 -> 202603 | BB11: =BA11+1 -> 202604 | BC11: =BB11+1 -> 202605 | BD11: =BC11+1 -> 202606 | BE11: =BD11+1 -> 202607 | BF11: =BE11+1 -> 202608 | BG11: =BF11+1 -> 202609 | ... BJ11: =BI11+1 -> 202612 | BK11: =+AY11+100 -> 202701 | BL11: =BK11+1 -> 202702 | BM11: =BL11+1 -> 202703 | BN11: =BM11+1 -> 202704 | BO11: =BN11+1 -> 202705 | BP11: =BO11+1 -> 202706 | BQ11: =BP11+1 -> 202707 | BR11: =BQ11+1 -> 202708 | BS11: =BR11+1 -> 202709 | ... BV11: =BU11+1 -> 202712
B12: Column | C12: 337 | D12: 338 | E12: 339 | F12: 340 | G12: 341 | H12: 342 | I12: 343 | J12: 344 | K12: 345 | L12: 346 | M12: 347 | N12: 348 | O12: 349 | P12: 350 | Q12: 351 | R12: 352 | S12: 353 | T12: 354 | U12: 355 | V12: 356 | W12: 357 | X12: 358 | Y12: 359 | Z12: 360 | AA12: 361 | AB12: 362 | AC12: 363 | AD12: 364 | AE12: 365 | AF12: 366 | AG12: 367 | AH12: 368 | AI12: 369 | AJ12: 370 | AK12: 371 | AL12: 372 | AM12: 373 | AN12: 374 | AO12: 375 | AP12: 376 | AQ12: 377 | AR12: 378 | AS12: 379 | AT12: 380 | AU12: 381 | AV12: 382 | AW12: 383 | AX12: 384 | AY12: 385 | AZ12: 386 | BA12: 387 | BB12: 388 | BC12: 389 | BD12: 390 | BE12: 391 | BF12: 392 | BG12: 393 | BH12: 394 | BI12: 395 | BJ12: 396 | BK12: 397 | BL12: 398 | BM12: 399 | BN12: 400 | BO12: 401 | BP12: 402 | BQ12: 403 | BR12: 404 | BS12: 405 | BT12: 406 | BU12: 407 | BV12: 408
B13: Historical | C13: =IF(C11<=$D$7,1,0) -> 1 | D13: =IF(D11<=$D$7,1,0) -> 1 | E13: =IF(E11<=$D$7,1,0) -> 1 | F13: =IF(F11<=$D$7,1,0) -> 1 | G13: =IF(G11<=$D$7,1,0) -> 1 | H13: =IF(H11<=$D$7,1,0) -> 1 | I13: =IF(I11<=$D$7,1,0) -> 1 | J13: =IF(J11<=$D$7,1,0) -> 1 | ... BV13: =IF(BV11<=$D$7,1,0) -> 0

Sheet 2tab
A1: Table of Contents | B1: Table 2. Energy Prices
B2: ="U.S. Energy Information Administration | Short-Term Energy Outlook - "&Dates!D1 -> U.S. Energy Information Administration | Short-Term Energy Outlook - October 2026
A3: Forecast date: | C3: =Dates!D3 -> 2022 | O3: =C3+1 -> 2023 | AA3: =O3+1 -> 2024 | AM3: =AA3+1 -> 2025 | AY3: =AM3+1 -> 2026 | BK3: =AY3+1 -> 2027
A4: =TEXT(Dates!$D$2,"dddd, mmmm d, yyyy") -> Thursday, October 1, 2026 | C4: Jan | D4: Feb | E4: Mar | F4: Apr | G4: May | H4: Jun | I4: Jul | J4: Aug | K4: Sep | L4: Oct | M4: Nov | N4: Dec | O4: Jan | P4: Feb | Q4: Mar | R4: Apr | S4: May | T4: Jun | U4: Jul | V4: Aug | W4: Sep | X4: Oct | Y4: Nov | Z4: Dec | AA4: Jan | AB4: Feb | AC4: Mar | AD4: Apr | AE4: May | AF4: Jun | AG4: Jul | AH4: Aug | AI4: Sep | AJ4: Oct | AK4: Nov | AL4: Dec | AM4: Jan | AN4: Feb | AO4: Mar | AP4: Apr | AQ4: May | AR4: Jun | AS4: Jul | AT4: Aug | AU4: Sep | AV4: Oct | AW4: Nov | AX4: Dec | AY4: Jan | AZ4: Feb | BA4: Mar | BB4: Apr | BC4: May | BD4: Jun | BE4: Jul | BF4: Aug | BG4: Sep | BH4: Oct | BI4: Nov | BJ4: Dec | BK4: Jan | BL4: Feb | BM4: Mar | BN4: Apr | BO4: May | BP4: Jun | BQ4: Jul | BR4: Aug | BS4: Sep | BT4: Oct | BU4: Nov | BV4: Dec
B5: Crude Oil (dollars per barrel)
A6: WTIPUUS | B6: West Texas Intermediate Spot Average | C6: 83.22 | D6: 91.64 | E6: 108.5 | F6: 101.78 | G6: 109.55 | H6: 114.84 | I6: 101.62 | J6: 93.67 | K6: 84.26 | L6: 87.55 | M6: 84.37 | N6: 76.44 | O6: 78.12 | P6: 76.83 | Q6: 73.28 | R6: 79.45 | S6: 71.58 | T6: 70.25 | U6: 76.07 | V6: 81.39 | W6: 89.43 | X6: 85.64 | Y6: 77.69 | Z6: 71.9 | AA6: 74.15 | AB6: 77.25 | AC6: 81.28 | AD6: 85.35 | AE6: 80.02 | AF6: 79.77 | AG6: 81.8 | AH6: 76.68 | AI6: 70.24 | AJ6: 71.99 | AK6: 69.95 | AL6: 70.12 | AM6: 75.74 | AN6: 71.53 | AO6: 68.24 | AP6: 63.54 | AQ6: 62.17 | AR6: 68.17 | AS6: 68.39 | AT6: 64.86 | AU6: 63.96 | AV6: 60.89 | AW6: 60.06 | AX6: 57.97 | AY6: 60.04 | AZ6: 64.51 | BA6: 91.38 | BB6: 100.32 | BC6: 102.13 | BD6: 84.81 | BE6: 80.46 | BF6: 83.9 | BG6: 97.31 | BH6: 100 | BI6: 97 | BJ6: 94 | BK6: 93 | BL6: 91 | BM6: 89 | BN6: 86 | BO6: 83 | BP6: 80 | BQ6: 78 | BR6: 76 | BS6: 74 | BT6: 72 | BU6: 70 | BV6: 68
A7: BREPUUS | B7: Brent Spot Average | C7: 86.51 | D7: 97.13 | E7: 117.25 | F7: 104.58 | G7: 113.34 | H7: 122.71 | I7: 111.93 | J7: 100.45 | K7: 89.76 | L7: 93.33 | M7: 91.42 | N7: 80.92 | O7: 82.5 | P7: 82.59 | Q7: 78.43 | R7: 84.64 | S7: 75.47 | T7: 74.84 | U7: 80.11 | V7: 86.15 | W7: 93.72 | X7: 90.6 | Y7: 82.94 | Z7: 77.63 | AA7: 80.12 | AB7: 83.48 | AC7: 85.41 | AD7: 89.94 | AE7: 81.75 | AF7: 82.25 | AG7: 85.15 | AH7: 80.36 | AI7: 74.02 | AJ7: 75.63 | AK7: 74.35 | AL7: 73.86 | AM7: 79.27 | AN7: 75.44 | AO7: 72.73 | AP7: 68.13 | AQ7: 64.45 | AR7: 71.44 | AS7: 71.04 | AT7: 67.87 | AU7: 67.99 | AV7: 64.54 | AW7: 63.8 | AX7: 62.54 | AY7: 66.6 | AZ7: 70.89 | BA7: 103.13 | BB7: 117.29 | BC7: 107.14 | BD7: 85.4 | BE7: 83.76 | BF7: 91.08 | BG7: 114.16 | BH7: 111 | BI7: 104 | BJ7: 99 | BK7: 97 | BL7: 95 | BM7: 93 | BN7: 90 | BO7: 87 | BP7: 84 | BQ7: 82 | BR7: 80 | BS7: 78 | BT7: 76 | BU7: 74 | BV7: 72
A8: RAIMUUS | B8: U.S. Imported Average | C8: 76.92 | D8: 87.73 | E8: 104.39 | F8: 102.7 | G8: 108.71 | H8: 112.06 | I8: 99.67 | J8: 92.21 | K8: 83.3 | L8: 84.26 | M8: 79.31 | N8: 70.89 | O8: 70.32 | P8: 69.67 | Q8: 68.53 | R8: 75.23 | S8: 70.05 | T8: 69.58 | U8: 74.83 | V8: 81.1 | W8: 87.14 | X8: 83.21 | Y8: 76.42 | Z8: 68.09 | AA8: 69.28 | AB8: 72.91 | AC8: 75.88 | AD8: 81.87 | AE8: 78.34 | AF8: 78.79 | AG8: 79.67 | AH8: 74.67 | AI8: 69.61 | AJ8: 70.91 | AK8: 69.08 | AL8: 68.21 | AM8: 72.65 | AN8: 71.14 | AO8: 67.48 | AP8: 63.53 | AQ8: 61.82 | AR8: 67.4 | AS8: 68.42 | AT8: 65.55 | AU8: 64.66 | AV8: 60.95 | AW8: 59.82 | AX8: 57.26 | AY8: 59.05 | AZ8: 61.43 | BA8: 84.81 | BB8: 95.97 | BC8: 99.01 | BD8: 83.77 | BE8: 79.94 | BF8: 85.15 | BG8: 97.81 | BH8: 100 | BI8: 97 | BJ8: 93.75 | BK8: 92.5 | BL8: 90.5 | BM8: 88.5 | BN8: 85.5 | BO8: 82.5 | BP8: 79.5 | BQ8: 77.5 | BR8: 75.5 | BS8: 73.5 | BT8: 71.5 | BU8: 69.5 | BV8: 67.5
A9: RACPUUS | B9: U.S. Refiner Average Acquisition Cost | C9: 80.26 | D9: 90.21 | E9: 106.98 | F9: 105.22 | G9: 110.43 | H9: 114.44 | I9: 102.82 | J9: 95.8 | K9: 86.57 | L9: 88.02 | M9: 84.57 | N9: 76.56 | O9: 75.7 | P9: 74.86 | Q9: 73 | R9: 78.53 | S9: 72.57 | T9: 71.39 | U9: 76.41 | V9: 81.78 | W9: 89.32 | X9: 86.6 | Y9: 79.7 | Z9: 72.34 | AA9: 73.28 | AB9: 76.2 | AC9: 79.67 | AD9: 84.47 | AE9: 80.7 | AF9: 80.28 | AG9: 81.5 | AH9: 77.39 | AI9: 71.75 | AJ9: 72.95 | AK9: 70.89 | AL9: 70.37 | AM9: 74.93 | AN9: 73.04 | AO9: 69.94 | AP9: 65.38 | AQ9: 63.26 | AR9: 68.11 | AS9: 69.3 | AT9: 66.73 | AU9: 65.66 | AV9: 62.4 | AW9: 61.22 | AX9: 59.09 | AY9: 60.6 | AZ9: 63.69 | BA9: 86.95 | BB9: 98.52 | BC9: 104.62 | BD9: 88.3 | BE9: 82.25 | BF9: 86.15 | BG9: 98.81 | BH9: 101 | BI9: 98 | BJ9: 94.75 | BK9: 93.5 | BL9: 91.5 | BM9: 89.5 | BN9: 86.5 | BO9: 83.5 | BP9: 80.5 | BQ9: 78.5 | BR9: 76.5 | BS9: 74.5 | BT9: 72.5 | BU9: 70.5 | BV9: 68.5
B10: U.S. Liquid Fuels (dollars per gallon)
B11: Wholesale Petroleum Product Prices
A12: MGWHUUS_$ | B12: Gasoline | C12: 2.423 | D12: 2.639 | E12: 3.232 | F12: 3.259524 | G12: 3.866024 | H12: 4.123384 | I12: 3.37644 | J12: 3.051836 | K12: 2.903245 | L12: 3.001381 | M12: 2.703665 | N12: 2.290825 | O12: 2.616023 | P12: 2.604257 | Q12: 2.6338603 | R12: 2.7438576 | S12: 2.5814268 | T12: 2.6152203 | U12: 2.7934427 | V12: 3.017008 | W12: 3.068549 | X12: 2.489302 | Y12: 2.298701 | Z12: 2.198293 | AA12: 2.2642827 | AB12: 2.4352118 | AC12: 2.6523563 | AD12: 2.8034567 | AE12: 2.5435091 | AF12: 2.4114264 | AG12: 2.4652096 | AH12: 2.3917494 | AI12: 2.1459177 | AJ12: 2.1766365 | AK12: 2.1050561 | AL12: 2.0561835 | AM12: 2.1951967 | AN12: 2.2283397 | AO12: 2.1666084 | AP12: 2.1332112 | AQ12: 2.1693844 | AR12: 2.1937824 | AS12: 2.2164929 | AT12: 2.2258001 | AU12: 2.2261596 | AV12: 2.0748897 | AW12: 2.0923868 | AX12: 1.8511045 | AY12: 2.1686121 | AZ12: 2.1644564 | BA12: 3.0289522 | BB12: 3.3926399 | BC12: 3.622145 | BD12: 3.1255834 | BE12: 3.3444168 | BF12: 3.374161 | BG12: 3.763112 | BH12: 3.610297 | BI12: 3.275319 | BJ12: 2.917237 | BK12: 2.831213 | BL12: 2.803454 | BM12: 2.877085 | BN12: 2.835565 | BO12: 2.780266 | BP12: 2.701686 | BQ12: 2.637112 | BR12: 2.592892 | BS12: 2.470454 | BT12: 2.353286 | BU12: 2.250647 | BV12: 2.105131
A13: DSWHUUS_$ | B13: Diesel Fuel | C13: 2.55 | D13: 2.83 | E13: 3.582 | F13: 3.952168 | G13: 4.230304 | H13: 4.354181 | I13: 3.687039 | J13: 3.567166 | K13: 3.453025 | L13: 4.137786 | M13: 3.62411 | N13: 3.052208 | O13: 3.259149 | P13: 2.850264 | Q13: 2.7421945 | R13: 2.5714561 | S13: 2.3690454 | T13: 2.4273615 | U13: 2.6877344 | V13: 3.1552607 | W13: 3.3905764 | X13: 3.1139361 | Y13: 2.8301277 | Z13: 2.5413234 | AA13: 2.6464436 | AB13: 2.7776207 | AC13: 2.672315 | AD13: 2.6386357 | AE13: 2.4383424 | AF13: 2.4533054 | AG13: 2.4777911 | AH13: 2.2974442 | AI13: 2.1415838 | AJ13: 2.2395334 | AK13: 2.2342254 | AL13: 2.2120718 | AM13: 2.4848 | AN13: 2.4513003 | AO13: 2.2489421 | AP13: 2.1503305 | AQ13: 2.094235 | AR13: 2.2935677 | AS13: 2.4590416 | AT13: 2.3019035 | AU13: 2.3852203 | AV13: 2.319493 | AW13: 2.4826256 | AX13: 2.1866896 | AY13: 2.2112701 | AZ13: 2.4229404 | BA13: 3.9229456 | BB13: 4.0241645 | BC13: 3.9668317 | BD13: 3.4302382 | BE13: 3.9358088 | BF13: 4.274197 | BG13: 4.966365 | BH13: 4.612366 | BI13: 4.214901 | BJ13: 3.843751 | BK13: 3.711694 | BL13: 3.545705 | BM13: 3.44155 | BN13: 3.236883 | BO13: 3.119964 | BP13: 3.002305 | BQ13: 2.942074 | BR13: 2.923776 | BS13: 2.902178 | BT13: 2.88666 | BU13: 2.847998 | BV13: 2.718639
A14: D2WHUUS_$ | B14: Fuel Oil | C14: 2.438 | D14: 2.742 | E14: 3.479 | F14: 3.864783 | G14: 4.494754 | H14: 4.18532 | I14: 3.591544 | J14: 3.412712 | K14: 3.341541 | L14: 4.211442 | M14: 3.826814 | N14: 2.957732 | O14: 3.0788 | P14: 2.654222 | Q14: 2.573933 | R14: 2.437445 | S14: 2.185012 | T14: 2.287781 | U14: 2.50541 | V14: 2.9400909 | W14: 3.1662828 | X14: 3.001917 | Y14: 2.813689 | Z14: 2.5459834 | AA14: 2.5953427 | AB14: 2.7072129 | AC14: 2.6060087 | AD14: 2.5428887 | AE14: 2.3542464 | AF14: 2.3597796 | AG14: 2.3602564 | AH14: 2.1745295 | AI14: 1.7110238 | AJ14: 1.9201808 | AK14: 2.1522056 | AL14: 2.1461987 | AM14: 2.4155888 | AN14: 2.3550538 | AO14: 2.1596369 | AP14: 2.0437682 | AQ14: 1.9982382 | AR14: 2.1857825 | AS14: 2.33366 | AT14: 2.1889565 | AU14: 2.253234 | AV14: 2.2012605 | AW14: 2.3846004 | AX14: 2.1246106 | AY14: 2.1228793 | AZ14: 2.3624801 | BA14: 3.7970055 | BB14: 3.8293963 | BC14: 3.7926012 | BD14: 3.2980729 | BE14: 3.7925204 | BF14: 4.104248 | BG14: 4.763588 | BH14: 4.463734 | BI14: 4.145768 | BJ14: 3.845517 | BK14: 3.706212 | BL14: 3.537361 | BM14: 3.339777 | BN14: 3.123334 | BO14: 3.080527 | BP14: 2.974322 | BQ14: 2.890798 | BR14: 2.85228 | BS14: 2.836538 | BT14: 2.824898 | BU14: 2.812241 | BV14: 2.70721
A15: JKTCUUS_$ | B15: Jet Fuel | C15: 2.451 | D15: 2.653 | E15: 3.326 | F15: 3.932723 | G15: 3.951999 | H15: 4.110857 | I15: 3.514584 | J15: 3.373692 | K15: 3.315124 | L15: 3.791592 | M15: 3.224217 | N15: 2.9516 | O15: 3.582719 | P15: 2.837045 | Q15: 2.734995 | R15: 2.439242 | S15: 2.240125 | T15: 2.31604 | U15: 2.549004 | V15: 3.040018 | W15: 3.1691723 | X15: 2.9347374 | Y15: 2.7908432 | Z15: 2.449858 | AA15: 2.6446613 | AB15: 2.7406133 | AC15: 2.6505441 | AD15: 2.6639904 | AE15: 2.4435652 | AF15: 2.4567522 | AG15: 2.4818477 | AH15: 2.2432841 | AI15: 2.0528699 | AJ15: 2.137127 | AK15: 2.1344906 | AL15: 2.1657768 | AM15: 2.4106396 | AN15: 2.3296536 | AO15: 2.1380438 | AP15: 2.0470011 | AQ15: 2.0004993 | AR15: 2.1628284 | AS15: 2.3102673 | AT15: 2.09439 | AU15: 2.15826 | AV15: 2.2220705 | AW15: 2.3238254 | AX15: 2.0364516 | AY15: 2.1012556 | AZ15: 2.3281572 | BA15: 3.7350089 | BB15: 3.961372 | BC15: 3.9754043 | BD15: 3.0920778 | BE15: 3.4463973 | BF15: 3.761341 | BG15: 4.398873 | BH15: 4.15438 | BI15: 3.857803 | BJ15: 3.626249 | BK15: 3.555807 | BL15: 3.443214 | BM15: 3.328323 | BN15: 3.135803 | BO15: 3.004611 | BP15: 2.885144 | BQ15: 2.821733 | BR15: 2.780497 | BS15: 2.736749 | BT15: 2.749463 | BU15: 2.723555 | BV15: 2.618401
A16: RFTCUUS_$ | B16: No. 6 Residual Fuel Oil (a) | C16: 2.16 | D16: 2.432 | E16: 2.867 | F16: 2.554918 | G16: 2.559421 | H16: 2.63757 | I16: 2.447322 | J16: 2.330931 | K16: 2.119986 | L16: 2.069518 | M16: 2.038687 | N16: 1.906479 | O16: 1.975822 | P16: 1.992127 | Q16: 1.916112 | R16: 1.955614 | S16: 1.887325 | T16: 1.844454 | U16: 1.889449 | V16: 2.029447 | W16: 2.17346 | X16: 2.15926 | Y16: 2.074986 | Z16: 1.942538 | AA16: 1.934969 | AB16: 1.979068 | AC16: 2.022677 | AD16: 2.083714 | AE16: 2.058375 | AF16: 2.048824 | AG16: 2.052829 | AH16: 2.02411 | AI16: 1.890567 | AJ16: 1.845031 | AK16: 1.834432 | AL16: 1.826336 | AM16: 1.917216 | AN16: 1.868652 | AO16: 1.799095 | AP16: 1.620718 | AQ16: 1.547472 | AR16: 1.654084 | AS16: 1.680695 | AT16: 1.622532 | AU16: 1.587192 | AV16: 1.499387 | AW16: 1.530801 | AX16: 1.52872 | AY16: 1.560502 | AZ16: 1.666759 | BA16: 2.233464 | BB16: 2.50102 | BC16: 2.610863 | BD16: 2.288061 | BE16: 2.183361 | BF16: 2.251722 | BG16: 2.484747 | BH16: 2.511507 | BI16: 2.493672 | BJ16: 2.457649 | BK16: 2.415783 | BL16: 2.385426 | BM16: 2.354452 | BN16: 2.225176 | BO16: 2.137818 | BP16: 2.071691 | BQ16: 2.032128 | BR16: 1.997389 | BS16: 1.950965 | BT16: 1.888602 | BU16: 1.880168 | BV16: 1.860991
A17: PRMBUUS_$ | B17: Propane Mont Belvieu Spot | C17: 1.169 | D17: 1.283 | E17: 1.448 | F17: 1.302 | G17: 1.223 | H17: 1.219 | I17: 1.142 | J17: 1.093 | K17: 0.991 | L17: 0.859 | M17: 0.852 | N17: 0.692 | O17: 0.842 | P17: 0.828 | Q17: 0.794 | R17: 0.811 | S17: 0.666 | T17: 0.574 | U17: 0.629 | V17: 0.679 | W17: 0.73 | X17: 0.67477273 | Y17: 0.6392381 | Z17: 0.68705 | AA17: 0.82128571 | AB17: 0.90755 | AC17: 0.8029 | AD17: 0.80009091 | AE17: 0.69768182 | AF17: 0.762 | AG17: 0.79733333 | AH17: 0.75477273 | AI17: 0.65565 | AJ17: 0.7736087 | AK17: 0.806 | AL17: 0.77266667 | AM17: 0.901 | AN17: 0.925 | AO17: 0.87 | AP17: 0.846 | AQ17: 0.746 | AR17: 0.756 | AS17: 0.711 | AT17: 0.66966667 | AU17: 0.68828571 | AV17: 0.63817391 | AW17: 0.60472222 | AX17: 0.64571429 | AY17: 0.62178947 | AZ17: 0.614 | BA17: 0.72709091 | BB17: 0.76571429 | BC17: 0.83 | BD17: 0.755 | BE17: 0.703 | BF17: 0.68833333 | BG17: 0.848 | BH17: 0.8225807 | BI17: 0.7693516 | BJ17: 0.7396745 | BK17: 0.7352188 | BL17: 0.747777 | BM17: 0.7366617 | BN17: 0.721156 | BO17: 0.7149421 | BP17: 0.6957847 | BQ17: 0.7023236 | BR17: 0.6894887 | BS17: 0.678077 | BT17: 0.6505168 | BU17: 0.6354158 | BV17: 0.6358004
B18: Retail Prices Including Taxes
A19: MGRARUS_$ | B19: Gasoline Regular Grade (b) | C19: 3.3146 | D19: 3.51725 | E19: 4.22175 | F19: 4.1085 | G19: 4.4436 | H19: 4.929 | I19: 4.55925 | J19: 3.975 | K19: 3.70025 | L19: 3.8152 | M19: 3.685 | N19: 3.21 | O19: 3.3392 | P19: 3.38875 | Q19: 3.422 | R19: 3.603 | S19: 3.5548 | T19: 3.571 | U19: 3.597 | V19: 3.83975 | W19: 3.836 | X19: 3.6128 | Y19: 3.318 | Z19: 3.134 | AA19: 3.0754 | AB19: 3.2115 | AC19: 3.4255 | AD19: 3.6114 | AE19: 3.603 | AF19: 3.4545 | AG19: 3.4838 | AH19: 3.38925 | AI19: 3.2138 | AJ19: 3.137 | AK19: 3.05275 | AL19: 3.0176 | AM19: 3.0755 | AN19: 3.12075 | AO19: 3.0964 | AP19: 3.17125 | AQ19: 3.15 | AR19: 3.1502 | AS19: 3.12475 | AT19: 3.1325 | AU19: 3.1656 | AV19: 3.05975 | AW19: 3.0495 | AX19: 2.8944 | AY19: 2.8085 | AZ19: 2.9075 | BA19: 3.6376 | BB19: 4.1025 | BC19: 4.47925 | BD19: 4.0496 | BE19: 3.93225 | BF19: 4.058 | BG19: 4.35475 | BH19: 4.404485 | BI19: 4.196543 | BJ19: 3.857073 | BK19: 3.72091 | BL19: 3.65105 | BM19: 3.737781 | BN19: 3.776932 | BO19: 3.766282 | BP19: 3.722974 | BQ19: 3.649884 | BR19: 3.569486 | BS19: 3.450378 | BT19: 3.367397 | BU19: 3.254546 | BV19: 3.107808
A20: MGEIAUS_$ | B20: Gasoline All Grades (b) | C20: 3.4128 | D20: 3.611 | E20: 4.32175 | F20: 4.21275 | G20: 4.545 | H20: 5.03225 | I20: 4.668 | J20: 4.0874 | K20: 3.81675 | L20: 3.9354 | M20: 3.79925 | N20: 3.3235 | O20: 3.4452 | P20: 3.50125 | Q20: 3.535 | R20: 3.71075 | S20: 3.6662 | T20: 3.68425 | U20: 3.7124 | V20: 3.95425 | W20: 3.9575 | X20: 3.742 | Y20: 3.4425 | Z20: 3.257 | AA20: 3.1968 | AB20: 3.32825 | AC20: 3.5415 | AD20: 3.7334 | AE20: 3.72525 | AF20: 3.5755 | AG20: 3.6004 | AH20: 3.5065 | AI20: 3.3384 | AJ20: 3.2605 | AK20: 3.17525 | AL20: 3.1394 | AM20: 3.19625 | AN20: 3.24725 | AO20: 3.223 | AP20: 3.2985 | AQ20: 3.278 | AR20: 3.2764 | AS20: 3.2495 | AT20: 3.25775 | AU20: 3.2934 | AV20: 3.19025 | AW20: 3.17925 | AX20: 3.0238 | AY20: 2.93625 | AZ20: 3.03925 | BA20: 3.7714 | BB20: 4.23575 | BC20: 4.60875 | BD20: 4.1838 | BE20: 4.06425 | BF20: 4.1918 | BG20: 4.49075 | BH20: 4.543146 | BI20: 4.336604 | BJ20: 3.997944 | BK20: 3.861085 | BL20: 3.789327 | BM20: 3.87482 | BN20: 3.915503 | BO20: 3.903642 | BP20: 3.859254 | BQ20: 3.788015 | BR20: 3.708632 | BS20: 3.591127 | BT20: 3.510425 | BU20: 3.398626 | BV20: 3.252416
A21: DSRTUUS_$ | B21: On-highway Diesel Fuel | C21: 3.7242 | D21: 4.03225 | E21: 5.1045 | F21: 5.1195 | G21: 5.571 | H21: 5.7535 | I21: 5.48575 | J21: 5.0132 | K21: 4.9925 | L21: 5.2114 | M21: 5.255 | N21: 4.7135 | O21: 4.5764 | P21: 4.41325 | Q21: 4.2105 | R21: 4.099 | S21: 3.915 | T21: 3.80175 | U21: 3.8822 | V21: 4.37025 | W21: 4.56275 | X21: 4.5068 | Y21: 4.25375 | Z21: 3.97175 | AA21: 3.8544 | AB21: 4.04375 | AC21: 4.022 | AD21: 4.0022 | AE21: 3.82225 | AF21: 3.722 | AG21: 3.8102 | AH21: 3.6995 | AI21: 3.5578 | AJ21: 3.58525 | AK21: 3.52175 | AL21: 3.4942 | AM21: 3.63425 | AN21: 3.67475 | AO21: 3.585 | AP21: 3.5665 | AQ21: 3.499 | AR21: 3.599 | AS21: 3.7785 | AT21: 3.74375 | AU21: 3.7484 | AV21: 3.6785 | AW21: 3.82225 | AX21: 3.6148 | AY21: 3.5225 | AZ21: 3.72225 | BA21: 4.9206 | BB21: 5.50125 | BC21: 5.5995 | BD21: 5.0238 | BE21: 4.95525 | BF21: 5.462 | BG21: 6.29075 | BH21: 6.269729 | BI21: 5.788287 | BJ21: 5.335352 | BK21: 5.058996 | BL21: 4.906298 | BM21: 4.798191 | BN21: 4.671997 | BO21: 4.581005 | BP21: 4.451405 | BQ21: 4.359721 | BR21: 4.282545 | BS21: 4.25247 | BT21: 4.221095 | BU21: 4.211961 | BV21: 4.107362
A22: D2RCAUS_$ | B22: Heating Oil | C22: 3.776 | D22: 4.058 | E22: 4.928 | F22: 5.143 | G22: 5.973 | H22: 5.863 | I22: 5.256 | J22: 4.953 | K22: 4.815 | L22: 5.786 | M22: 5.24 | N22: 4.344 | O22: 4.313 | P22: 3.988 | Q22: 3.866 | R22: 3.709 | S22: 3.423 | T22: 3.395 | U22: 3.472 | V22: 3.819 | W22: 4.151 | X22: 4.089 | Y22: 4.011 | Z22: 3.821 | AA22: 3.766 | AB22: 3.828 | AC22: 3.774 | AD22: 3.706 | AE22: 3.694 | AF22: 3.576 | AG22: 3.683 | AH22: 3.545 | AI22: 3.394 | AJ22: 3.427 | AK22: 3.41 | AL22: 3.458 | AM22: 3.793 | AN22: 3.827 | AO22: 3.625 | AP22: 3.506 | AQ22: 3.433 | AR22: 3.463 | AS22: 3.627 | AT22: 3.58 | AU22: 3.592 | AV22: 3.6595 | AW22: 3.727 | AX22: 3.66 | AY22: 3.579 | AZ22: 3.99 | BA22: 5.045 | BB22: 5.291 | BC22: 5.293 | BD22: 4.713 | BE22: 4.799 | BF22: 5.145 | BG22: 5.968658 | BH22: 6.145958 | BI22: 5.791571 | BJ22: 5.455083 | BK22: 5.256054 | BL22: 5.062226 | BM22: 4.844742 | BN22: 4.5605 | BO22: 4.451544 | BP22: 4.284316 | BQ22: 4.170591 | BR22: 4.105057 | BS22: 4.151998 | BT22: 4.179061 | BU22: 4.145087 | BV22: 4.052569
A23: PRRCAUS | B23: Propane Residential | C23: 2.737 | D23: 2.846 | E23: 2.9925 | F23: - | G23: - | H23: - | I23: - | J23: - | K23: 2.661 | L23: 2.66375 | M23: 2.6754 | N23: 2.68075 | O23: 2.70075 | P23: 2.703 | Q23: 2.684 | R23: - | S23: - | T23: - | U23: - | V23: - | W23: 2.379 | X23: 2.3945 | Y23: 2.4248 | Z23: 2.4635 | AA23: 2.559 | AB23: 2.60775 | AC23: 2.5826667 | AD23: 2.567 | AE23: 2.475 | AF23: 2.412 | AG23: 2.394 | AH23: 2.371 | AI23: 2.369 | AJ23: 2.427 | AK23: 2.48325 | AL23: 2.51825 | AM23: 2.6812 | AN23: 2.74825 | AO23: 2.7136667 | AP23: 2.640946 | AQ23: 2.520224 | AR23: - | AS23: - | AT23: - | AU23: - | AV23: 2.4308 | AW23: 2.4625 | AX23: 2.537 | AY23: 2.58825 | AZ23: 2.659 | BA23: 2.6716667 | BB23: - | BC23: - | BD23: - | BE23: - | BF23: - | BG23: - | BH23: 2.511039 | BI23: 2.513857 | BJ23: 2.51909 | BK23: 2.523345 | BL23: 2.525562 | BM23: 2.517246 | BN23: - | BO23: - | BP23: - | BQ23: - | BR23: - | BS23: - | BT23: 2.352275 | BU23: 2.344237 | BV23: 2.350456
B24: Natural Gas
A25: NGHHMCF | B25: Henry Hub Spot (dollars per thousand cubic feet) | C25: 4.54644 | D25: 4.86822 | E25: 5.0862 | F25: 6.8508 | G25: 8.44932 | H25: 7.9926 | I25: 7.55664 | J25: 9.14478 | K25: 8.17944 | L25: 5.87508 | M25: 5.6571 | N25: 5.74014 | O25: 3.39426 | P25: 2.47044 | Q25: 2.39778 | R25: 2.24208 | S25: 2.2317 | T25: 2.26284 | U25: 2.6469 | V25: 2.67804 | W25: 2.74032 | X25: 3.09324 | Y25: 2.81298 | Z25: 2.61576 | AA25: 3.30402 | AB25: 1.78708 | AC25: 1.54811 | AD25: 1.6624 | AE25: 2.20268 | AF25: 2.63906 | AG25: 2.15073 | AH25: 2.06761 | AI25: 2.36892 | AJ25: 2.2858 | AK25: 2.20268 | AL25: 3.12739 | AM25: 4.29107 | AN25: 4.35341 | AO25: 4.28068 | AP25: 3.55338 | AQ25: 3.24168 | AR25: 3.13778 | AS25: 3.3248 | AT25: 3.02349 | AU25: 3.08583 | AV25: 3.31441 | AW25: 3.93781 | AX25: 4.42614 | AY25: 8.02108 | AZ25: 3.76118 | BA25: 3.15856 | BB25: 2.87803 | BC25: 3.05466 | BD25: 3.27285 | BE25: 3.00271 | BF25: 2.88842 | BG25: 3.06505 | BH25: 3.26991 | BI25: 3.370805 | BJ25: 3.63643 | BK25: 4.161397 | BL25: 3.641905 | BM25: 3.016885 | BN25: 2.695908 | BO25: 2.685389 | BP25: 2.858136 | BQ25: 3.060944 | BR25: 3.198991 | BS25: 3.23011 | BT25: 3.259816 | BU25: 3.561927 | BV25: 4.054492
A26: NGHHUUS | B26: Henry Hub Spot (dollars per million Btu) | C26: 4.38 | D26: 4.69 | E26: 4.9 | F26: 6.6 | G26: 8.14 | H26: 7.7 | I26: 7.28 | J26: 8.81 | K26: 7.88 | L26: 5.66 | M26: 5.45 | N26: 5.53 | O26: 3.27 | P26: 2.38 | Q26: 2.31 | R26: 2.16 | S26: 2.15 | T26: 2.18 | U26: 2.55 | V26: 2.58 | W26: 2.64 | X26: 2.98 | Y26: 2.71 | Z26: 2.52 | AA26: 3.18 | AB26: 1.72 | AC26: 1.49 | AD26: 1.6 | AE26: 2.12 | AF26: 2.54 | AG26: 2.07 | AH26: 1.99 | AI26: 2.28 | AJ26: 2.2 | AK26: 2.12 | AL26: 3.01 | AM26: 4.13 | AN26: 4.19 | AO26: 4.12 | AP26: 3.42 | AQ26: 3.12 | AR26: 3.02 | AS26: 3.2 | AT26: 2.91 | AU26: 2.97 | AV26: 3.19 | AW26: 3.79 | AX26: 4.26 | AY26: 7.72 | AZ26: 3.62 | BA26: 3.04 | BB26: 2.77 | BC26: 2.94 | BD26: 3.15 | BE26: 2.89 | BF26: 2.78 | BG26: 2.95 | BH26: 3.147171 | BI26: 3.244279 | BJ26: 3.499933 | BK26: 4.005195 | BL26: 3.505203 | BM26: 2.903643 | BN26: 2.594714 | BO26: 2.58459 | BP26: 2.750853 | BQ26: 2.946048 | BR26: 3.078914 | BS26: 3.108864 | BT26: 3.137455 | BU26: 3.428227 | BV26: 3.902303
B27: U.S. Retail Prices (dollars per thousand cubic feet)
A28: NGICUUS | B28: Industrial Sector | C28: 6.49 | D28: 7.34 | E28: 6.2 | F28: 6.7 | G28: 8.11 | H28: 9.34 | I28: 7.89 | J28: 9.44 | K28: 9.62 | L28: 7.18 | M28: 6.76 | N28: 8.08 | O28: 7.2 | P28: 5.94 | Q28: 5 | R28: 4.03 | S28: 3.54 | T28: 3.53 | U28: 3.84 | V28: 3.79 | W28: 3.84 | X28: 4.06 | Y28: 4.35 | Z28: 4.48 | AA28: 5.24 | AB28: 4.97 | AC28: 3.9 | AD28: 3.48 | AE28: 3.31 | AF28: 3.85 | AG28: 3.74 | AH28: 3.22 | AI28: 3.4 | AJ28: 3.94 | AK28: 4.04 | AL28: 5.21 | AM28: 6.03 | AN28: 5.92 | AO28: 5.68 | AP28: 5.31 | AQ28: 4.69 | AR28: 4.66 | AS28: 4.64 | AT28: 4.47 | AU28: 4.42 | AV28: 4.55 | AW28: 5.33 | AX28: 6.37 | AY28: 7.2 | AZ28: 8.43 | BA28: 5.27 | BB28: 4.8 | BC28: 4.19 | BD28: 4.36 | BE28: 4.58 | BF28: 3.669638 | BG28: 3.765838 | BH28: 3.889474 | BI28: 4.130057 | BJ28: 4.731174 | BK28: 5.196312 | BL28: 5.099824 | BM28: 3.965331 | BN28: 3.511777 | BO28: 3.339236 | BP28: 3.598066 | BQ28: 3.595127 | BR28: 3.682079 | BS28: 3.83612 | BT28: 3.854715 | BU28: 4.248003 | BV28: 5.039924
A29: NGCCUUS | B29: Commercial Sector | C29: 9.78 | D29: 10.04 | E29: 10.22 | F29: 10.61 | G29: 12.09 | H29: 13.44 | I29: 13.51 | J29: 14.14 | K29: 14.55 | L29: 12.85 | M29: 11.89 | N29: 11.97 | O29: 12.56 | P29: 12.11 | Q29: 11.05 | R29: 10.51 | S29: 10.56 | T29: 10.81 | U29: 10.98 | V29: 11.19 | W29: 11 | X29: 10.18 | Y29: 9.76 | Z29: 9.91 | AA29: 9.5 | AB29: 10.03 | AC29: 9.99 | AD29: 9.93 | AE29: 10.35 | AF29: 10.7 | AG29: 11.08 | AH29: 10.75 | AI29: 10.78 | AJ29: 10.43 | AK29: 10.1 | AL29: 9.82 | AM29: 9.88 | AN29: 10.32 | AO29: 11.12 | AP29: 11.48 | AQ29: 11.82 | AR29: 12.18 | AS29: 12.77 | AT29: 12.55 | AU29: 12.13 | AV29: 11.27 | AW29: 10.75 | AX29: 10.95 | AY29: 11.26 | AZ29: 12.34 | BA29: 12.26 | BB29: 12.21 | BC29: 12.17 | BD29: 12.71 | BE29: 13.03 | BF29: 12.45633 | BG29: 12.09457 | BH29: 10.75839 | BI29: 10.01158 | BJ29: 9.815196 | BK29: 9.785206 | BL29: 9.715065 | BM29: 9.659286 | BN29: 9.590433 | BO29: 9.975645 | BP29: 10.31645 | BQ29: 10.27971 | BR29: 10.31172 | BS29: 10.2299 | BT29: 9.352553 | BU29: 8.852007 | BV29: 8.939901
A30: NGRCUUS | B30: Residential Sector | C30: 12.04 | D30: 12.15 | E30: 12.94 | F30: 13.97 | G30: 17.68 | H30: 22.41 | I30: 24.57 | J30: 25.39 | K30: 24.52 | L30: 18.62 | M30: 15.56 | N30: 14.66 | O30: 15.56 | P30: 15.15 | Q30: 13.88 | R30: 14.54 | S30: 16.86 | T30: 20.31 | U30: 22.18 | V30: 23.41 | W30: 22.05 | X30: 16.85 | Y30: 13.47 | Z30: 13.03 | AA30: 11.89 | AB30: 13.14 | AC30: 13.66 | AD30: 14.32 | AE30: 17.67 | AF30: 20.72 | AG30: 22.78 | AH30: 23.22 | AI30: 22.46 | AJ30: 18.38 | AK30: 14.79 | AL30: 12.85 | AM30: 12.44 | AN30: 12.97 | AO30: 14.62 | AP30: 16.17 | AQ30: 19.26 | AR30: 23.21 | AS30: 25.44 | AT30: 26.26 | AU30: 24.7 | AV30: 19.34 | AW30: 15.07 | AX30: 14.09 | AY30: 13.96 | AZ30: 14.95 | BA30: 16.16 | BB30: 18.04 | BC30: 19.73 | BD30: 24.09 | BE30: 26.45 | BF30: 26.10853 | BG30: 23.99755 | BH30: 18.29067 | BI30: 14.43695 | BJ30: 13.32436 | BK30: 12.70758 | BL30: 13.32643 | BM30: 13.80558 | BN30: 14.47218 | BO30: 16.46118 | BP30: 19.64333 | BQ30: 21.20412 | BR30: 21.89885 | BS30: 20.6046 | BT30: 16.08915 | BU30: 13.00405 | BV30: 12.24026
B31: U.S. Electricity
B32: Power Generation Fuel Costs (dollars per million Btu)
A33: CLEUDUS | B33: Coal | C33: 2.1999998 | D33: 2.1699924 | E33: 2.1519612 | F33: 2.1814959 | G33: 2.2321288 | H33: 2.3155552 | I33: 2.4693298 | J33: 2.5065243 | K33: 2.5078223 | L33: 2.4609092 | M33: 2.4777313 | N33: 2.6450428 | O33: 2.5903686 | P33: 2.5892527 | Q33: 2.4979914 | R33: 2.4713572 | S33: 2.5092991 | T33: 2.4623011 | U33: 2.4738064 | V33: 2.4908999 | W33: 2.5303278 | X33: 2.5308088 | Y33: 2.5057356 | Z33: 2.4743834 | AA33: 2.480634 | AB33: 2.481884 | AC33: 2.4990103 | AD33: 2.5358312 | AE33: 2.5624788 | AF33: 2.5077763 | AG33: 2.4719804 | AH33: 2.4424825 | AI33: 2.4158504 | AJ33: 2.4734106 | AK33: 2.4189353 | AL33: 2.4001598 | AM33: 2.4074516 | AN33: 2.421892 | AO33: 2.4480426 | AP33: 2.4750664 | AQ33: 2.4976898 | AR33: 2.4556935 | AS33: 2.4038538 | AT33: 2.405235 | AU33: 2.4085215 | AV33: 2.3886598 | AW33: 2.3943676 | AX33: 2.384865 | AY33: 2.445418 | AZ33: 2.3940255 | BA33: 2.4122787 | BB33: 2.4173443 | BC33: 2.43272 | BD33: 2.5142711 | BE33: 2.4901709 | BF33: 2.476831 | BG33: 2.463847 | BH33: 2.448576 | BI33: 2.455878 | BJ33: 2.474572 | BK33: 2.480109 | BL33: 2.47318 | BM33: 2.475268 | BN33: 2.48165 | BO33: 2.485892 | BP33: 2.465773 | BQ33: 2.464159 | BR33: 2.465931 | BS33: 2.456321 | BT33: 2.440641 | BU33: 2.437408 | BV33: 2.448634
A34: NGEUDUS | B34: Natural Gas | C34: 6.5615686 | D34: 5.9972805 | E34: 5.099995 | F34: 6.2112152 | G34: 7.5658022 | H34: 8.0109598 | I34: 7.5251205 | J34: 9.0036782 | K34: 8.145977 | L34: 5.8016812 | M34: 5.7086231 | N34: 8.9206061 | O34: 7.0480799 | P34: 4.3766907 | Q34: 3.3688402 | R34: 2.6996565 | S34: 2.5466016 | T34: 2.5965598 | U34: 2.9999011 | V34: 2.9442115 | W34: 2.8748365 | X34: 2.9244336 | Y34: 3.3889109 | Z34: 3.2818353 | AA34: 4.8608805 | AB34: 2.9022369 | AC34: 2.1884128 | AD34: 2.0471063 | AE34: 2.2880624 | AF34: 2.682151 | AG34: 2.5068161 | AH34: 2.2496043 | AI34: 2.3651181 | AJ34: 2.6065868 | AK34: 2.6334468 | AL34: 3.854503 | AM34: 5.8751661 | AN34: 4.8104435 | AO34: 4.1730049 | AP34: 3.5806145 | AQ34: 3.2834531 | AR34: 3.3355906 | AS34: 3.5245462 | AT34: 3.1676547 | AU34: 3.040961 | AV34: 3.0820127 | AW34: 3.8880261 | AX34: 5.0377259 | AY34: 9.8066621 | AZ34: 6.2766333 | BA34: 3.1079723 | BB34: 2.7849867 | BC34: 2.7515765 | BD34: 3.1656973 | BE34: 3.3545949 | BF34: 2.929044 | BG34: 2.926976 | BH34: 3.260307 | BI34: 3.4737 | BJ34: 3.892388 | BK34: 4.541216 | BL34: 3.997166 | BM34: 3.226678 | BN34: 2.818042 | BO34: 2.715966 | BP34: 2.756391 | BQ34: 2.947337 | BR34: 3.082379 | BS34: 3.071227 | BT34: 3.243388 | BU34: 3.637616 | BV34: 4.27906
A35: RFEUDUS | B35: Residual Fuel Oil (c) | C35: 15.49 | D35: 16.49 | E35: 20.33 | F35: 25.06 | G35: 26.15 | H35: 26.3 | I35: 30.36 | J35: 25.72 | K35: 23.76 | L35: 21.76 | M35: 23.74 | N35: 19.86 | O35: 19.44 | P35: 18.56 | Q35: 19.92 | R35: 18.77 | S35: 18.11 | T35: 16.82 | U35: 16.74 | V35: 19.03 | W35: 22.2 | X35: 21.47 | Y35: 20.75 | Z35: 20.25 | AA35: 18.22 | AB35: 18.94 | AC35: 19.67 | AD35: 19.24 | AE35: 18.81 | AF35: 17.68 | AG35: 18.15 | AH35: 18.23 | AI35: 17.08 | AJ35: 15.76 | AK35: 16.25 | AL35: 16.43 | AM35: 16.07 | AN35: 17.06 | AO35: 15.83 | AP35: 15.6 | AQ35: 15.05 | AR35: 15.04 | AS35: 16.16 | AT35: 16.12 | AU35: 15.34 | AV35: 15.67 | AW35: 15.41 | AX35: 15.02 | AY35: 13.99 | AZ35: 13.38 | BA35: 17.93 | BB35: 26.96 | BC35: 28.72 | BD35: 24.722943 | BE35: 22.07856 | BF35: 20.26397 | BG35: 21.05765 | BH35: 22.43643 | BI35: 22.20281 | BJ35: 21.54878 | BK35: 20.60188 | BL35: 19.51952 | BM35: 19.26324 | BN35: 19.30056 | BO35: 18.28567 | BP35: 18.07054 | BQ35: 17.09106 | BR35: 16.30672 | BS35: 15.76808 | BT35: 15.39264 | BU35: 15.10246 | BV35: 15.17616
A36: DKEUDUS | B36: Distillate Fuel Oil | C36: 20.1 | D36: 20.79 | E36: 25.68 | F36: 28.32 | G36: 30.12 | H36: 33.02 | I36: 27.38 | J36: 26.9 | K36: 25.57 | L36: 27.81 | M36: 29.28 | N36: 23.17 | O36: 24.09 | P36: 23.1 | Q36: 21.42 | R36: 20.9 | S36: 19.87 | T36: 19.21 | U36: 19.84 | V36: 23 | W36: 24.18 | X36: 24.23 | Y36: 21.75 | Z36: 20.74 | AA36: 19.64 | AB36: 20.84 | AC36: 20.6 | AD36: 20.84 | AE36: 19.44 | AF36: 18.62 | AG36: 19.57 | AH36: 18.37 | AI36: 17.79 | AJ36: 17.32 | AK36: 18.85 | AL36: 17.67 | AM36: 18.9 | AN36: 18.42 | AO36: 17.42 | AP36: 17.9 | AQ36: 16.75 | AR36: 17.64 | AS36: 18.39 | AT36: 17.81 | AU36: 18.13 | AV36: 18.07 | AW36: 18.3 | AX36: 17.33 | AY36: 17.73 | AZ36: 17.69 | BA36: 23.17 | BB36: 31.5 | BC36: 32.26 | BD36: 24.916677 | BE36: 24.922234 | BF36: 30.52351 | BG36: 35.6348 | BH36: 34.9223 | BI36: 32.8993 | BJ36: 30.06292 | BK36: 28.63397 | BL36: 27.4239 | BM36: 26.74096 | BN36: 25.16216 | BO36: 23.99369 | BP36: 23.29778 | BQ36: 22.88019 | BR36: 22.31765 | BS36: 22.02371 | BT36: 21.96388 | BU36: 22.13803 | BV36: 21.19718
B37: Prices to Ultimate Customers (cents per kilowatthour)
A38: ESICUUS | B38: Industrial Sector | C38: 7.19 | D38: 7.28 | E38: 7.37 | F38: 7.7 | G38: 8.25 | H38: 8.85 | I38: 9.31 | J38: 9.38 | K38: 9.06 | L38: 8.45 | M38: 8.14 | N38: 8.5 | O38: 8.18 | P38: 8.01 | Q38: 7.8 | R38: 7.51 | S38: 7.64 | T38: 8.11 | U38: 8.36 | V38: 8.9 | W38: 8.43 | X38: 8.01 | Y38: 7.79 | Z38: 7.61 | AA38: 8.07 | AB38: 7.76 | AC38: 7.68 | AD38: 7.79 | AE38: 7.87 | AF38: 8.41 | AG38: 8.73 | AH38: 8.67 | AI38: 8.45 | AJ38: 8.11 | AK38: 7.85 | AL38: 7.96 | AM38: 8.34 | AN38: 8.24 | AO38: 8.26 | AP38: 8.21 | AQ38: 8.29 | AR38: 8.9 | AS38: 9.33 | AT38: 9.08 | AU38: 9.02 | AV38: 8.65 | AW38: 8.44 | AX38: 8.53 | AY38: 9.29 | AZ38: 8.95 | BA38: 8.58 | BB38: 8.66 | BC38: 8.71 | BD38: 9.17 | BE38: 9.77 | BF38: 9.578867 | BG38: 9.576994 | BH38: 8.855703 | BI38: 8.588459 | BJ38: 8.747557 | BK38: 9.150509 | BL38: 9.282663 | BM38: 8.879003 | BN38: 8.943528 | BO38: 8.880692 | BP38: 9.336129 | BQ38: 9.752235 | BR38: 9.546863 | BS38: 9.426411 | BT38: 8.949652 | BU38: 8.710285 | BV38: 8.876048
A39: ESCMUUS | B39: Commercial Sector | C39: 11.26 | D39: 11.66 | E39: 11.65 | F39: 11.82 | G39: 12 | H39: 12.75 | I39: 13.02 | J39: 13.41 | K39: 13.28 | L39: 12.89 | M39: 12.33 | N39: 12.28 | O39: 12.61 | P39: 12.53 | Q39: 12.36 | R39: 12.08 | S39: 12.16 | T39: 12.63 | U39: 12.91 | V39: 13.08 | W39: 13.07 | X39: 12.73 | Y39: 12.43 | Z39: 12.24 | AA39: 12.5 | AB39: 12.53 | AC39: 12.47 | AD39: 12.35 | AE39: 12.32 | AF39: 12.89 | AG39: 13.37 | AH39: 13.16 | AI39: 13.23 | AJ39: 12.89 | AK39: 12.35 | AL39: 12.64 | AM39: 12.82 | AN39: 12.98 | AO39: 13.16 | AP39: 12.89 | AQ39: 12.93 | AR39: 13.54 | AS39: 14.05 | AT39: 13.93 | AU39: 13.99 | AV39: 13.49 | AW39: 13.19 | AX39: 13.63 | AY39: 13.64 | AZ39: 14.37 | BA39: 13.92 | BB39: 13.51 | BC39: 13.54 | BD39: 14.19 | BE39: 14.53 | BF39: 14.3861 | BG39: 14.38018 | BH39: 13.83311 | BI39: 13.49232 | BJ39: 13.93594 | BK39: 13.94813 | BL39: 14.65019 | BM39: 14.20737 | BN39: 13.83212 | BO39: 13.7936 | BP39: 14.41666 | BQ39: 14.77397 | BR39: 14.46678 | BS39: 14.51181 | BT39: 14.00428 | BU39: 13.64976 | BV39: 14.10122
A40: ESRCUUS | B40: Residential Sector | C40: 13.64 | D40: 13.76 | E40: 14.41 | F40: 14.57 | G40: 14.89 | H40: 15.3 | I40: 15.31 | J40: 15.82 | K40: 16.19 | L40: 15.99 | M40: 15.55 | N40: 14.94 | O40: 15.47 | P40: 15.98 | Q40: 16.04 | R40: 16.1 | S40: 16.14 | T40: 16.09 | U40: 15.86 | V40: 15.91 | W40: 16.27 | X40: 16.48 | Y40: 16.19 | Z40: 15.69 | AA40: 15.41 | AB40: 16.1 | AC40: 16.67 | AD40: 16.86 | AE40: 16.4 | AF40: 16.38 | AG40: 16.62 | AH40: 16.6 | AI40: 16.82 | AJ40: 17.09 | AK40: 16.85 | AL40: 16.27 | AM40: 15.94 | AN40: 16.43 | AO40: 17.09 | AP40: 17.55 | AQ40: 17.37 | AR40: 17.47 | AS40: 17.45 | AT40: 17.61 | AU40: 18.08 | AV40: 17.97 | AW40: 17.78 | AX40: 17.24 | AY40: 17.45 | AZ40: 17.65 | BA40: 18.56 | BB40: 18.83 | BC40: 18.44 | BD40: 18.34 | BE40: 18.31 | BF40: 18.31218 | BG40: 18.42258 | BH40: 18.40701 | BI40: 18.33735 | BJ40: 17.79294 | BK40: 18.08291 | BL40: 18.11152 | BM40: 18.92103 | BN40: 19.37601 | BO40: 18.88527 | BP40: 18.70345 | BQ40: 18.71772 | BR40: 18.72533 | BS40: 19.09038 | BT40: 18.83241 | BU40: 18.73716 | BV40: 18.22717
...

Sheet 3atab
A1: Table of Contents | B1: Table 3a. World Petroleum and Other Liquid Fuels Production, Consumption, and Inventories
B2: ="U.S. Energy Information Administration | Short-Term Energy Outlook - "&Dates!D1 -> U.S. Energy Information Administration | Short-Term Energy Outlook - October 2026
A3: Forecast date: | C3: =Dates!D3 -> 2022 | O3: =C3+1 -> 2023 | AA3: =O3+1 -> 2024 | AM3: =AA3+1 -> 2025 | AY3: =AM3+1 -> 2026 | BK3: =AY3+1 -> 2027
A4: =TEXT(Dates!$D$2,"dddd, mmmm d, yyyy") -> Thursday, October 1, 2026 | C4: Jan | D4: Feb | E4: Mar | F4: Apr | G4: May | H4: Jun | I4: Jul | J4: Aug | K4: Sep | L4: Oct | M4: Nov | N4: Dec | O4: Jan | P4: Feb | Q4: Mar | R4: Apr | S4: May | T4: Jun | U4: Jul | V4: Aug | W4: Sep | X4: Oct | Y4: Nov | Z4: Dec | AA4: Jan | AB4: Feb | AC4: Mar | AD4: Apr | AE4: May | AF4: Jun | AG4: Jul | AH4: Aug | AI4: Sep | AJ4: Oct | AK4: Nov | AL4: Dec | AM4: Jan | AN4: Feb | AO4: Mar | AP4: Apr | AQ4: May | AR4: Jun | AS4: Jul | AT4: Aug | AU4: Sep | AV4: Oct | AW4: Nov | AX4: Dec | AY4: Jan | AZ4: Feb | BA4: Mar | BB4: Apr | BC4: May | BD4: Jun | BE4: Jul | BF4: Aug | BG4: Sep | BH4: Oct | BI4: Nov | BJ4: Dec | BK4: Jan | BL4: Feb | BM4: Mar | BN4: Apr | BO4: May | BP4: Jun | BQ4: Jul | BR4: Aug | BS4: Sep | BT4: Oct | BU4: Nov | BV4: Dec
B5: Production (million barrels per day) (a)
A6: papr_world | B6: World total | C6: 98.160102 | D6: 99.39694 | E6: 99.885464 | F6: 99.309545 | G6: 99.291762 | H6: 99.803794 | I6: 100.92805 | J6: 101.47355 | K6: 102.00623 | L6: 102.15839 | M6: 102.33529 | N6: 100.71309 | O6: 101.45483 | P6: 102.05691 | Q6: 102.41224 | R6: 102.18205 | S6: 101.70521 | T6: 102.59023 | U6: 102.10171 | V6: 101.83323 | W6: 102.89053 | X6: 103.17737 | Y6: 103.9633 | Z6: 103.94838 | AA6: 101.50298 | AB6: 102.7523 | AC6: 103.52942 | AD6: 103.4216 | AE6: 103.01944 | AF6: 103.02363 | AG6: 103.1858 | AH6: 103.51233 | AI6: 102.41426 | AJ6: 103.75461 | AK6: 103.89638 | AL6: 103.80399 | AM6: 102.69922 | AN6: 103.24108 | AO6: 104.76969 | AP6: 104.48322 | AQ6: 104.9752 | AR6: 106.12079 | AS6: 107.216 | AT6: 107.67391 | AU6: 108.83613 | AV6: 108.57775 | AW6: 108.69134 | AX6: 108.00186 | AY6: 105.96457 | AZ6: 108.70947 | BA6: 96.785843 | BB6: 95.42844 | BC6: 94.5832 | BD6: 99.522681 | BE6: 102.03867 | BF6: 100.41344 | BG6: 101.30379 | BH6: 102.10466 | BI6: 103.09166 | BJ6: 103.70899 | BK6: 104.76212 | BL6: 106.31727 | BM6: 107.267 | BN6: 108.56879 | BO6: 109.83623 | BP6: 110.22941 | BQ6: 110.74984 | BR6: 110.90402 | BS6: 111.103 | BT6: 111.35784 | BU6: 111.81915 | BV6: 111.49122
A7: copr_world | B7: Crude oil | C7: 74.605008 | D7: 75.880613 | E7: 75.753379 | F7: 75.141954 | G7: 74.502345 | H7: 74.796448 | I7: 75.746687 | J7: 76.788716 | K7: 77.320606 | L7: 77.266407 | M7: 77.386292 | N7: 76.806249 | O7: 76.850895 | P7: 77.457482 | Q7: 77.464207 | R7: 76.817181 | S7: 76.219464 | T7: 76.703195 | U7: 76.076301 | V7: 75.63138 | W7: 76.584197 | X7: 76.79819 | Y7: 77.558317 | Z7: 77.817932 | AA7: 76.431129 | AB7: 77.127675 | AC7: 77.516653 | AD7: 77.007654 | AE7: 76.337687 | AF7: 76.045517 | AG7: 76.363938 | AH7: 76.583755 | AI7: 75.530679 | AJ7: 76.501376 | AK7: 76.718409 | AL7: 77.105934 | AM7: 76.710274 | AN7: 76.933542 | AO7: 78.064069 | AP7: 77.604759 | AQ7: 77.704555 | AR7: 78.786773 | AS7: 79.2781 | AT7: 79.736721 | AU7: 81.005011 | AV7: 80.812841 | AW7: 80.68081 | AX7: 80.572001 | AY7: 79.142675 | AZ7: 81.201708 | BA7: 72.009003 | BB7: 71.026877 | BC7: 69.713226 | BD7: 74.043846 | BE7: 76.029776 | BF7: 75.074818 | BG7: 75.971593 | BH7: 76.31424 | BI7: 77.061897 | BJ7: 77.676994 | BK7: 78.695206 | BL7: 79.874973 | BM7: 80.252718 | BN7: 80.770178 | BO7: 81.480541 | BP7: 81.64256 | BQ7: 82.036717 | BR7: 82.140286 | BS7: 82.416825 | BT7: 82.579692 | BU7: 83.027691 | BV7: 82.973332
A8: world_nc | B8: Other liquids | C8: 23.555095 | D8: 23.516328 | E8: 24.132085 | F8: 24.167591 | G8: 24.789417 | H8: 25.007345 | I8: 25.181359 | J8: 24.684833 | K8: 24.685622 | L8: 24.891987 | M8: 24.949002 | N8: 23.906845 | O8: 24.603933 | P8: 24.599426 | Q8: 24.948033 | R8: 25.364872 | S8: 25.485744 | T8: 25.887036 | U8: 26.025409 | V8: 26.201848 | W8: 26.30633 | X8: 26.379177 | Y8: 26.40498 | Z8: 26.130443 | AA8: 25.071851 | AB8: 25.624624 | AC8: 26.012768 | AD8: 26.413944 | AE8: 26.681751 | AF8: 26.978117 | AG8: 26.821862 | AH8: 26.92857 | AI8: 26.883583 | AJ8: 27.253237 | AK8: 27.177969 | AL8: 26.698054 | AM8: 25.988941 | AN8: 26.307542 | AO8: 26.705616 | AP8: 26.878457 | AQ8: 27.270647 | AR8: 27.334021 | AS8: 27.937902 | AT8: 27.937187 | AU8: 27.831123 | AV8: 27.764912 | AW8: 28.010526 | AX8: 27.429858 | AY8: 26.8219 | AZ8: 27.507763 | BA8: 24.77684 | BB8: 24.401564 | BC8: 24.869974 | BD8: 25.478835 | BE8: 26.008898 | BF8: 25.338627 | BG8: 25.3322 | BH8: 25.79042 | BI8: 26.029765 | BJ8: 26.031991 | BK8: 26.066914 | BL8: 26.442298 | BM8: 27.014283 | BN8: 27.798609 | BO8: 28.355692 | BP8: 28.586847 | BQ8: 28.713124 | BR8: 28.763738 | BS8: 28.68617 | BT8: 28.778149 | BU8: 28.791459 | BV8: 28.517884
A10: papr_world | B10: World total | C10: 98.160102 | D10: 99.39694 | E10: 99.885464 | F10: 99.309545 | G10: 99.291762 | H10: 99.803794 | I10: 100.92805 | J10: 101.47355 | K10: 102.00623 | L10: 102.15839 | M10: 102.33529 | N10: 100.71309 | O10: 101.45483 | P10: 102.05691 | Q10: 102.41224 | R10: 102.18205 | S10: 101.70521 | T10: 102.59023 | U10: 102.10171 | V10: 101.83323 | W10: 102.89053 | X10: 103.17737 | Y10: 103.9633 | Z10: 103.94838 | AA10: 101.50298 | AB10: 102.7523 | AC10: 103.52942 | AD10: 103.4216 | AE10: 103.01944 | AF10: 103.02363 | AG10: 103.1858 | AH10: 103.51233 | AI10: 102.41426 | AJ10: 103.75461 | AK10: 103.89638 | AL10: 103.80399 | AM10: 102.69922 | AN10: 103.24108 | AO10: 104.76969 | AP10: 104.48322 | AQ10: 104.9752 | AR10: 106.12079 | AS10: 107.216 | AT10: 107.67391 | AU10: 108.83613 | AV10: 108.57775 | AW10: 108.69134 | AX10: 108.00186 | AY10: 105.96457 | AZ10: 108.70947 | BA10: 96.785843 | BB10: 95.42844 | BC10: 94.5832 | BD10: 99.522681 | BE10: 102.03867 | BF10: 100.41344 | BG10: 101.30379 | BH10: 102.10466 | BI10: 103.09166 | BJ10: 103.70899 | BK10: 104.76212 | BL10: 106.31727 | BM10: 107.267 | BN10: 108.56879 | BO10: 109.83623 | BP10: 110.22941 | BQ10: 110.74984 | BR10: 110.90402 | BS10: 111.103 | BT10: 111.35784 | BU10: 111.81915 | BV10: 111.49122
A11: papr_opec | B11: OPEC total (b) | C11: 28.2382 | D11: 28.8921 | E11: 28.531 | F11: 28.8233 | G11: 28.3442 | H11: 28.472 | I11: 28.692 | J11: 29.6076 | K11: 29.7493 | L11: 29.3482 | M11: 29.0533 | N11: 29.046 | O11: 28.4971 | P11: 28.8 | Q11: 29.0451 | R11: 29.117 | S11: 28.5837 | T11: 28.7967 | U11: 27.9514 | V11: 27.7859 | W11: 28.4556 | X11: 28.3649 | Y11: 28.4316 | Z11: 28.3614 | AA11: 28.1501 | AB11: 28.465 | AC11: 28.7935 | AD11: 28.7524 | AE11: 28.6014 | AF11: 28.2004 | AG11: 28.6383 | AH11: 28.557 | AI11: 27.8274 | AJ11: 28.3263 | AK11: 28.3405 | AL11: 28.4935 | AM11: 28.5002 | AN11: 28.6269 | AO11: 28.8728 | AP11: 28.701 | AQ11: 29.073 | AR11: 29.5506 | AS11: 29.1376 | AT11: 29.1594 | AU11: 30.3216 | AV11: 30.0734 | AW11: 29.8504 | AX11: 30.0989 | AY11: 29.9734 | AZ11: 30.8166 | BA11: 21.9029 | BB11: 19.9506 | BC11: 19.3833 | BD11: 21.7619 | BE11: 24.019993 | BF11: 22.888373 | BG11: 23.85159 | BH11: 23.969294 | BI11: 24.312508 | BJ11: 24.845792 | BK11: 25.71206 | BL11: 27.045558 | BM11: 27.873271 | BN11: 28.732466 | BO11: 29.710497 | BP11: 30.023859 | BQ11: 30.051848 | BR11: 30.10483 | BS11: 30.137887 | BT11: 30.17066 | BU11: 30.213881 | BV11: 30.247171
A12: copr_opec | B12: Crude oil | C12: 23.79 | D12: 24.45 | E12: 24.085 | F12: 24.37 | G12: 23.8946 | H12: 24.02 | I12: 24.24 | J12: 25.17 | K12: 25.31 | L12: 24.905 | M12: 24.61 | N12: 24.66 | O12: 24.055 | P12: 24.34 | Q12: 24.555 | R12: 24.56 | S12: 24.085 | T12: 24.235 | U12: 23.39 | V12: 23.175 | W12: 23.825 | X12: 23.715 | Y12: 23.77 | Z12: 23.7 | AA12: 23.54 | AB12: 23.845 | AC12: 24.175 | AD12: 24.13 | AE12: 23.98 | AF12: 23.58 | AG12: 24.02 | AH12: 23.94 | AI12: 23.21 | AJ12: 23.71 | AK12: 23.725 | AL12: 23.88 | AM12: 23.87 | AN12: 24 | AO12: 24.25 | AP12: 24.055 | AQ12: 24.41 | AR12: 24.91 | AS12: 24.46 | AT12: 24.435 | AU12: 25.58 | AV12: 25.295 | AW12: 25.055 | AX12: 25.225 | AY12: 25.125 | AZ12: 25.95 | BA12: 18.45 | BB12: 16.9 | BC12: 16.41 | BD12: 18.61 | BE12: 20.58 | BF12: 19.86 | BG12: 20.8 | BH12: 20.76 | BI12: 20.945 | BJ12: 21.23 | BK12: 21.84 | BL12: 22.92 | BM12: 23.485 | BN12: 24.05 | BO12: 24.815 | BP12: 25.08 | BQ12: 25.09 | BR12: 25.105 | BS12: 25.12 | BT12: 25.135 | BU12: 25.15 | BV12: 25.165
A13: opec_nc | B13: Other liquids | C13: 4.4482 | D13: 4.4421 | E13: 4.446 | F13: 4.4533 | G13: 4.4496 | H13: 4.452 | I13: 4.452 | J13: 4.4376 | K13: 4.4393 | L13: 4.4432 | M13: 4.4433 | N13: 4.386 | O13: 4.4421 | P13: 4.46 | Q13: 4.4901 | R13: 4.557 | S13: 4.4987 | T13: 4.5617 | U13: 4.5614 | V13: 4.6109 | W13: 4.6306 | X13: 4.6499 | Y13: 4.6616 | Z13: 4.6614 | AA13: 4.6101 | AB13: 4.62 | AC13: 4.6185 | AD13: 4.6224 | AE13: 4.6214 | AF13: 4.6204 | AG13: 4.6183 | AH13: 4.617 | AI13: 4.6174 | AJ13: 4.6163 | AK13: 4.6155 | AL13: 4.6135 | AM13: 4.6302 | AN13: 4.6269 | AO13: 4.6228 | AP13: 4.646 | AQ13: 4.663 | AR13: 4.6406 | AS13: 4.6776 | AT13: 4.7244 | AU13: 4.7416 | AV13: 4.7784 | AW13: 4.7954 | AX13: 4.8739 | AY13: 4.8484 | AZ13: 4.8666 | BA13: 3.4529 | BB13: 3.0506 | BC13: 2.9733 | BD13: 3.1519 | BE13: 3.439993 | BF13: 3.0283732 | BG13: 3.0515897 | BH13: 3.2092944 | BI13: 3.3675084 | BJ13: 3.615792 | BK13: 3.8720595 | BL13: 4.1255582 | BM13: 4.3882711 | BN13: 4.6824661 | BO13: 4.8954965 | BP13: 4.9438589 | BQ13: 4.9618476 | BR13: 4.9998302 | BS13: 5.017887 | BT13: 5.0356605 | BU13: 5.0638809 | BV13: 5.0821707
A14: papr_nonopec | B14: Non-OPEC total | C14: 69.921902 | D14: 70.50484 | E14: 71.354464 | F14: 70.486245 | G14: 70.947562 | H14: 71.331794 | I14: 72.236046 | J14: 71.865949 | K14: 72.256928 | L14: 72.810194 | M14: 73.281993 | N14: 71.667094 | O14: 72.957728 | P14: 73.256909 | Q14: 73.36714 | R14: 73.065053 | S14: 73.121508 | T14: 73.793532 | U14: 74.150309 | V14: 74.047328 | W14: 74.434927 | X14: 74.812467 | Y14: 75.531697 | Z14: 75.586975 | AA14: 73.35288 | AB14: 74.287299 | AC14: 74.735921 | AD14: 74.669198 | AE14: 74.418038 | AF14: 74.823234 | AG14: 74.5475 | AH14: 74.955325 | AI14: 74.586862 | AJ14: 75.428313 | AK14: 75.555878 | AL14: 75.310488 | AM14: 74.199015 | AN14: 74.614184 | AO14: 75.896885 | AP14: 75.782216 | AQ14: 75.902202 | AR14: 76.570194 | AS14: 78.078402 | AT14: 78.514508 | AU14: 78.514534 | AV14: 78.504353 | AW14: 78.840936 | AX14: 77.902959 | AY14: 75.991175 | AZ14: 77.892871 | BA14: 74.882943 | BB14: 75.47784 | BC14: 75.1999 | BD14: 77.760781 | BE14: 78.018681 | BF14: 77.525071 | BG14: 77.452203 | BH14: 78.135365 | BI14: 78.779154 | BJ14: 78.863193 | BK14: 79.050061 | BL14: 79.271713 | BM14: 79.39373 | BN14: 79.836322 | BO14: 80.125737 | BP14: 80.205548 | BQ14: 80.697993 | BR14: 80.799194 | BS14: 80.965108 | BT14: 81.18718 | BU14: 81.605269 | BV14: 81.244044
A15: copr_nonopec | B15: Crude oil | C15: 50.815008 | D15: 51.430613 | E15: 51.668379 | F15: 50.771954 | G15: 50.607745 | H15: 50.776448 | I15: 51.506687 | J15: 51.618716 | K15: 52.010606 | L15: 52.361407 | M15: 52.776292 | N15: 52.146249 | O15: 52.795895 | P15: 53.117482 | Q15: 52.909207 | R15: 52.257181 | S15: 52.134464 | T15: 52.468195 | U15: 52.686301 | V15: 52.45638 | W15: 52.759197 | X15: 53.08319 | Y15: 53.788317 | Z15: 54.117932 | AA15: 52.891129 | AB15: 53.282675 | AC15: 53.341653 | AD15: 52.877654 | AE15: 52.357687 | AF15: 52.465517 | AG15: 52.343938 | AH15: 52.643755 | AI15: 52.320679 | AJ15: 52.791376 | AK15: 52.993409 | AL15: 53.225934 | AM15: 52.840274 | AN15: 52.933542 | AO15: 53.814069 | AP15: 53.549759 | AQ15: 53.294555 | AR15: 53.876773 | AS15: 54.8181 | AT15: 55.301721 | AU15: 55.425011 | AV15: 55.517841 | AW15: 55.62581 | AX15: 55.347001 | AY15: 54.017675 | AZ15: 55.251708 | BA15: 53.559003 | BB15: 54.126877 | BC15: 53.303226 | BD15: 55.433846 | BE15: 55.449776 | BF15: 55.214818 | BG15: 55.171593 | BH15: 55.55424 | BI15: 56.116897 | BJ15: 56.446994 | BK15: 56.855206 | BL15: 56.954973 | BM15: 56.767718 | BN15: 56.720178 | BO15: 56.665541 | BP15: 56.56256 | BQ15: 56.946717 | BR15: 57.035286 | BS15: 57.296825 | BT15: 57.444692 | BU15: 57.877691 | BV15: 57.808332
A16: nonopec_nc | B16: Other liquids | C16: 19.106895 | D16: 19.074228 | E16: 19.686085 | F16: 19.714291 | G16: 20.339817 | H16: 20.555346 | I16: 20.729359 | J16: 20.247233 | K16: 20.246322 | L16: 20.448787 | M16: 20.505702 | N16: 19.520845 | O16: 20.161833 | P16: 20.139426 | Q16: 20.457933 | R16: 20.807872 | S16: 20.987044 | T16: 21.325336 | U16: 21.464009 | V16: 21.590948 | W16: 21.67573 | X16: 21.729277 | Y16: 21.74338 | Z16: 21.469043 | AA16: 20.461751 | AB16: 21.004624 | AC16: 21.394268 | AD16: 21.791544 | AE16: 22.060351 | AF16: 22.357717 | AG16: 22.203562 | AH16: 22.31157 | AI16: 22.266183 | AJ16: 22.636937 | AK16: 22.562469 | AL16: 22.084554 | AM16: 21.358741 | AN16: 21.680642 | AO16: 22.082816 | AP16: 22.232457 | AQ16: 22.607647 | AR16: 22.693421 | AS16: 23.260302 | AT16: 23.212787 | AU16: 23.089523 | AV16: 22.986512 | AW16: 23.215126 | AX16: 22.555958 | AY16: 21.9735 | AZ16: 22.641163 | BA16: 21.32394 | BB16: 21.350963 | BC16: 21.896674 | BD16: 22.326935 | BE16: 22.568905 | BF16: 22.310254 | BG16: 22.28061 | BH16: 22.581125 | BI16: 22.662257 | BJ16: 22.416199 | BK16: 22.194854 | BL16: 22.31674 | BM16: 22.626012 | BN16: 23.116143 | BO16: 23.460196 | BP16: 23.642988 | BQ16: 23.751276 | BR16: 23.763908 | BS16: 23.668283 | BT16: 23.742488 | BU16: 23.727578 | BV16: 23.435713
B18: Consumption (million barrels per day) (c)
A19: patc_world | B19: World total | C19: 97.189207 | D19: 100.43925 | E19: 99.206604 | F19: 97.903741 | G19: 99.184777 | H19: 100.98915 | I19: 100.21353 | J19: 100.77513 | K19: 101.0505 | L19: 98.823011 | M19: 100.35633 | N19: 100.93459 | O19: 97.968206 | P19: 101.59515 | Q19: 101.0466 | R19: 100.08296 | S19: 101.50017 | T19: 103.19684 | U19: 101.84594 | V19: 102.10939 | W19: 102.07224 | X19: 101.51919 | Y19: 102.4264 | Z19: 102.61281 | AA19: 100.04152 | AB19: 102.2192 | AC19: 101.61659 | AD19: 102.46945 | AE19: 103.44388 | AF19: 104.12409 | AG19: 104.28354 | AH19: 103.81393 | AI19: 103.69837 | AJ19: 104.01016 | AK19: 103.64493 | AL19: 103.85684 | AM19: 102.02773 | AN19: 103.67977 | AO19: 102.37159 | AP19: 103.82441 | AQ19: 103.72074 | AR19: 105.82237 | AS19: 105.62519 | AT19: 104.50203 | AU19: 105.99841 | AV19: 104.56484 | AW19: 104.51564 | AX19: 106.21376 | AY19: 102.37736 | AZ19: 104.37561 | BA19: 101.99885 | BB19: 99.47245 | BC19: 99.004661 | BD19: 101.68375 | BE19: 101.77342 | BF19: 103.38822 | BG19: 104.24142 | BH19: 102.77557 | BI19: 103.56289 | BJ19: 104.63473 | BK19: 101.98182 | BL19: 104.305 | BM19: 103.07931 | BN19: 103.98138 | BO19: 104.1172 | BP19: 105.70968 | BQ19: 105.60003 | BR19: 105.43423 | BS19: 105.57248 | BT19: 104.41458 | BU19: 105.2305 | BV19: 106.33015
A20: patc_oecd | B20: OECD total (d) | C20: 44.417921 | D20: 46.578628 | E20: 46.116716 | F20: 44.460787 | G20: 44.920732 | H20: 46.090795 | I20: 45.68746 | J20: 46.510202 | K20: 46.10796 | L20: 45.01877 | M20: 45.984572 | N20: 45.930398 | O20: 44.017648 | P20: 46.241946 | Q20: 45.900143 | R20: 44.550015 | S20: 45.502625 | T20: 46.643397 | U20: 45.73218 | V20: 46.351917 | W20: 45.660235 | X20: 46.253544 | Y20: 46.406301 | Z20: 45.995007 | AA20: 44.850888 | AB20: 45.615075 | AC20: 45.212189 | AD20: 45.782865 | AE20: 46.308222 | AF20: 46.440145 | AG20: 46.843938 | AH20: 47.078068 | AI20: 46.421636 | AJ20: 47.54112 | AK20: 46.346035 | AL20: 46.141826 | AM20: 45.53339 | AN20: 46.277971 | AO20: 45.21808 | AP20: 46.224649 | AQ20: 45.437867 | AR20: 46.872243 | AS20: 47.209993 | AT20: 46.467904 | AU20: 47.180873 | AV20: 46.880391 | AW20: 45.776965 | AX20: 46.841842 | AY20: 45.693993 | AZ20: 46.794035 | BA20: 45.325265 | BB20: 44.558133 | BC20: 43.635924 | BD20: 45.553658 | BE20: 46.061843 | BF20: 46.249644 | BG20: 46.235697 | BH20: 46.164469 | BI20: 45.82487 | BJ20: 46.162177 | BK20: 45.19359 | BL20: 46.43323 | BM20: 45.600969 | BN20: 45.626441 | BO20: 45.430433 | BP20: 46.32763 | BQ20: 46.792327 | BR20: 47.062959 | BS20: 46.343838 | BT20: 46.51882 | BU20: 46.184335 | BV20: 46.510498
A21: patc_ca | B21: Canada | C21: 2.3484 | D21: 2.436 | E21: 2.2049 | F21: 2.2264 | G21: 2.2724 | H21: 2.4964 | I21: 2.497 | J21: 2.4042 | K21: 2.3992 | L21: 2.416 | M21: 2.4947 | N21: 2.5164 | O21: 2.3085 | P21: 2.4065 | Q21: 2.3577 | R21: 2.2962 | S21: 2.3295 | T21: 2.7067 | U21: 2.7111 | V21: 2.6192 | W21: 2.379 | X21: 2.5911 | Y21: 2.4173 | Z21: 2.4804 | AA21: 2.4909 | AB21: 2.5119 | AC21: 2.3451 | AD21: 2.2791 | AE21: 2.4863 | AF21: 2.6126 | AG21: 2.6442 | AH21: 2.5912 | AI21: 2.5684 | AJ21: 2.5582 | AK21: 2.6295 | AL21: 2.4971 | AM21: 2.5324 | AN21: 2.5045 | AO21: 2.489 | AP21: 2.3827 | AQ21: 2.4139 | AR21: 2.4235 | AS21: 2.5767 | AT21: 2.5929 | AU21: 2.8024 | AV21: 2.6226 | AW21: 2.6905 | AX21: 2.6198 | AY21: 2.6255 | AZ21: 2.5046 | BA21: 2.5705 | BB21: 2.3387 | BC21: 2.562 | BD21: 2.4221 | BE21: 2.6176892 | BF21: 2.620963 | BG21: 2.5849268 | BH21: 2.5809794 | BI21: 2.5789499 | BJ21: 2.5385012 | BK21: 2.4999608 | BL21: 2.5394434 | BM21: 2.4176007 | BN21: 2.359511 | BO21: 2.4651778 | BP21: 2.5601759 | BQ21: 2.6054628 | BR21: 2.6087212 | BS21: 2.572854 | BT21: 2.5689251 | BU21: 2.5669051 | BV21: 2.526646
A22: patc_oecd_europe | B22: Europe | C22: 12.4541 | D22: 13.8018 | E22: 13.5509 | F22: 13.2777 | G22: 13.4484 | H22: 13.8619 | I22: 13.8403 | J22: 14.1251 | K22: 14.2387 | L22: 13.2733 | M22: 13.4586 | N22: 13.4722 | O22: 12.384 | P22: 13.6045 | Q22: 13.3716 | R22: 13.0635 | S22: 13.6596 | T22: 13.9265 | U22: 13.6174 | V22: 13.5559 | W22: 13.8008 | X22: 13.7425 | Y22: 13.3715 | Z22: 12.9773 | AA22: 12.6303 | AB22: 13.0562 | AC22: 12.9913 | AD22: 13.7607 | AE22: 13.4968 | AF22: 13.8041 | AG22: 14.3009 | AH22: 13.9267 | AI22: 14.0653 | AJ22: 14.1951 | AK22: 13.5074 | AL22: 13.0122 | AM22: 12.5639 | AN22: 13.4004 | AO22: 13.0878 | AP22: 13.8302 | AQ22: 13.4204 | AR22: 14.0746 | AS22: 13.9689 | AT22: 13.4016 | AU22: 14.0383 | AV22: 13.9239 | AW22: 13.0813 | AX22: 13.3951 | AY22: 12.6056 | AZ22: 13.3306 | BA22: 13.0973 | BB22: 13.0089 | BC22: 12.7901 | BD22: 13.7438 | BE22: 13.892468 | BF22: 13.768322 | BG22: 13.934755 | BH22: 13.735835 | BI22: 13.359059 | BJ22: 13.170068 | BK22: 12.627177 | BL22: 13.43667 | BM22: 13.257365 | BN22: 13.446693 | BO22: 13.319202 | BP22: 13.691627 | BQ22: 13.918735 | BR22: 13.793915 | BS22: 13.961252 | BT22: 13.761252 | BU22: 13.382429 | BV22: 13.192412
A23: patc_ja | B23: Japan | C23: 3.7721 | D23: 3.8104 | E23: 3.4808 | F23: 2.9713 | G23: 2.9195 | H23: 3.0845 | I23: 3.0638 | J23: 3.2804 | K23: 3.1186 | L23: 3.1934 | M23: 3.4178 | N23: 3.9667 | O23: 3.7177 | P23: 3.8748 | Q23: 3.4719 | R23: 3.1581 | S23: 2.9658 | T23: 3.0542 | U23: 3.0356 | V23: 3.0937 | W23: 3.065 | X23: 3.0504 | Y23: 3.4032 | Z23: 3.7131 | AA23: 3.4551 | AB23: 3.5293 | AC23: 3.3646 | AD23: 3.1215 | AE23: 2.9005 | AF23: 2.9046 | AG23: 2.8862 | AH23: 2.9821 | AI23: 2.9357 | AJ23: 2.9799 | AK23: 3.3248 | AL23: 3.5819 | AM23: 3.3909 | AN23: 3.473 | AO23: 3.2246 | AP23: 3.0791 | AQ23: 2.7432 | AR23: 2.8834 | AS23: 2.8528 | AT23: 2.901 | AU23: 2.9624 | AV23: 2.9636 | AW23: 3.1475 | AX23: 3.5341 | AY23: 3.385 | AZ23: 3.3684 | BA23: 3.1137 | BB23: 2.6912 | BC23: 2.5083 | BD23: 2.5604 | BE23: 2.7274376 | BF23: 2.8782887 | BG23: 2.8075603 | BH23: 2.8317982 | BI23: 3.1144454 | BJ23: 3.468224 | BK23: 3.279325 | BL23: 3.45928 | BM23: 3.1566738 | BN23: 2.8425254 | BO23: 2.6384979 | BP23: 2.6341644 | BQ23: 2.7311461 | BR23: 2.7963318 | BS23: 2.7273654 | BT23: 2.7509994 | BU23: 3.026605 | BV23: 3.3715698
A24: patc_us | B24: United States | C24: 19.613111 | D24: 20.190413 | E24: 20.483486 | F24: 19.727341 | G24: 19.839567 | H24: 20.433237 | I24: 19.925561 | J24: 20.265029 | K24: 20.129058 | L24: 20.006618 | M24: 20.214214 | N24: 19.327209 | O24: 19.353483 | P24: 19.941524 | Q24: 20.207293 | R24: 19.971915 | S24: 20.323443 | T24: 20.755186 | U24: 20.042789 | V24: 20.767872 | W24: 20.154583 | X24: 20.631444 | Y24: 20.73898 | Z24: 20.396183 | AA24: 19.789279 | AB24: 19.972378 | AC24: 20.011388 | AD24: 20.155279 | AE24: 20.887834 | AF24: 20.536577 | AG24: 20.593178 | AH24: 20.984949 | AI24: 20.356295 | AJ24: 21.249372 | AK24: 20.367203 | AL24: 20.615046 | AM24: 20.757864 | AN24: 20.363696 | AO24: 20.008059 | AP24: 20.44344 | AQ24: 20.532706 | AR24: 21.081529 | AS24: 21.191642 | AT24: 21.212545 | AU24: 20.868235 | AV24: 20.97257 | AW24: 20.493094 | AX24: 20.87032 | AY24: 20.649558 | AZ24: 21.137712 | BA24: 20.383077 | BB24: 20.808202 | BC24: 20.070571 | BD24: 20.735919 | BE24: 20.612007 | BF24: 20.567334 | BG24: 20.648288 | BH24: 20.75278 | BI24: 20.33729 | BJ24: 20.51759 | BK24: 20.41527 | BL24: 20.4602 | BM24: 20.36963 | BN24: 20.65121 | BO24: 20.64327 | BP24: 21.05979 | BQ24: 21.15904 | BR24: 21.4215 | BS24: 20.79518 | BT24: 21.14786 | BU24: 20.73438 | BV24: 20.87235
A25: patc_ust | B25: U.S. Territories | C25: 0.1040104 | D25: 0.10161547 | E25: 0.10802963 | F25: 0.10904599 | G25: 0.11336516 | H25: 0.11525827 | I25: 0.12529889 | J25: 0.12537328 | K25: 0.12590185 | L25: 0.11805177 | M25: 0.11675812 | N25: 0.11848859 | O25: 0.12076484 | P25: 0.11782243 | Q25: 0.12515005 | R25: 0.12649989 | S25: 0.1315817 | T25: 0.13361116 | U25: 0.14539096 | V25: 0.14564454 | W25: 0.14625241 | X25: 0.13739962 | Y25: 0.13582069 | Z25: 0.13762357 | AA25: 0.12540879 | AB25: 0.12239733 | AC25: 0.12990068 | AD25: 0.13138572 | AE25: 0.13658842 | AF25: 0.13866771 | AG25: 0.15085996 | AH25: 0.15111864 | AI25: 0.1517414 | AJ25: 0.14264785 | AK25: 0.14103217 | AL25: 0.14287997 | AM25: 0.12922594 | AN25: 0.12737492 | AO25: 0.14972071 | AP25: 0.12240929 | AQ25: 0.14206109 | AR25: 0.13971447 | AS25: 0.14485124 | AT25: 0.1508592 | AU25: 0.14203775 | AV25: 0.15492076 | AW25: 0.14487075 | AX25: 0.13332187 | AY25: 0.10723548 | AZ25: 0.10542261 | BA25: 0.12738761 | BB25: 0.10053122 | BC25: 0.1198528 | BD25: 0.11753904 | BE25: 0.12258845 | BF25: 0.1284971 | BG25: 0.11981826 | BH25: 0.13251854 | BI25: 0.12263512 | BJ25: 0.11126577 | BK25: 0.12596499 | BL25: 0.12417647 | BM25: 0.14589843 | BN25: 0.11933247 | BO25: 0.13844327 | BP25: 0.13615049 | BQ25: 0.14114414 | BR25: 0.14698939 | BS25: 0.13840158 | BT25: 0.15098523 | BU25: 0.14120815 | BV25: 0.12995338
A26: patc_other_oecd | B26: Other OECD | C26: 6.1262 | D26: 6.2384 | E26: 6.2886 | F26: 6.149 | G26: 6.3275 | H26: 6.0995 | I26: 6.2355 | J26: 6.3101 | K26: 6.0965 | L26: 6.0114 | M26: 6.2825 | N26: 6.5294 | O26: 6.1332 | P26: 6.2968 | Q26: 6.3665 | R26: 5.9338 | S26: 6.0927 | T26: 6.0672 | U26: 6.1799 | V26: 6.1696 | W26: 6.1146 | X26: 6.1007 | Y26: 6.3395 | Z26: 6.2904 | AA26: 6.3599 | AB26: 6.4229 | AC26: 6.3699 | AD26: 6.3349 | AE26: 6.4002 | AF26: 6.4436 | AG26: 6.2686 | AH26: 6.442 | AI26: 6.3442 | AJ26: 6.4159 | AK26: 6.3761 | AL26: 6.2927 | AM26: 6.1591 | AN26: 6.409 | AO26: 6.2589 | AP26: 6.3668 | AQ26: 6.1856 | AR26: 6.2695 | AS26: 6.4751 | AT26: 6.209 | AU26: 6.3675 | AV26: 6.2428 | AW26: 6.2197 | AX26: 6.2892 | AY26: 6.3211 | AZ26: 6.3473 | BA26: 6.0333 | BB26: 5.6106 | BC26: 5.5851 | BD26: 5.9739 | BE26: 6.0896533 | BF26: 6.2862391 | BG26: 6.1403483 | BH26: 6.1305574 | BI26: 6.3124902 | BJ26: 6.356528 | BK26: 6.2458921 | BL26: 6.4134605 | BM26: 6.2538017 | BN26: 6.2071684 | BO26: 6.2258416 | BP26: 6.2457218 | BQ26: 6.2367994 | BR26: 6.2955014 | BS26: 6.1487851 | BT26: 6.1387979 | BU26: 6.3328071 | BV26: 6.4175668
A27: patc_non_oecd | B27: Non-OECD total | C27: 52.771286 | D27: 53.860626 | E27: 53.089888 | F27: 53.442954 | G27: 54.264045 | H27: 54.898356 | I27: 54.52607 | J27: 54.264923 | K27: 54.942544 | L27: 53.804241 | M27: 54.371763 | N27: 55.004189 | O27: 53.950558 | P27: 55.353207 | Q27: 55.146461 | R27: 55.532944 | S27: 55.997546 | T27: 56.55344 | U27: 56.11376 | V27: 55.757471 | W27: 56.412003 | X27: 55.265644 | Y27: 56.020096 | Z27: 56.617808 | AA27: 55.190631 | AB27: 56.604129 | AC27: 56.404397 | AD27: 56.68659 | AE27: 57.135656 | AF27: 57.683941 | AG27: 57.439597 | AH27: 56.735862 | AI27: 57.276738 | AJ27: 56.469044 | AK27: 57.298895 | AL27: 57.715011 | AM27: 56.494344 | AN27: 57.401796 | AO27: 57.153507 | AP27: 57.599759 | AQ27: 58.282869 | AR27: 58.950125 | AS27: 58.415199 | AT27: 58.034126 | AU27: 58.817542 | AV27: 57.68445 | AW27: 58.738671 | AX27: 59.371916 | AY27: 56.683368 | AZ27: 57.581573 | BA27: 56.673582 | BB27: 54.914316 | BC27: 55.368737 | BD27: 56.130096 | BE27: 55.711577 | BF27: 57.138578 | BG27: 58.005722 | BH27: 56.611101 | BI27: 57.738025 | BJ27: 58.472549 | BK27: 56.788228 | BL27: 57.871765 | BM27: 57.478338 | BN27: 58.35494 | BO27: 58.686772 | BP27: 59.382046 | BQ27: 58.807707 | BR27: 58.371269 | BS27: 59.228638 | BT27: 57.895757 | BU27: 59.046161 | BV27: 59.819652
